<?xml version="1.0" ?>
<robot name="mr_robot" xmlns:xacro="http://www.ros.org/wiki/xacro">

<xacro:include filename="$(find mr_robot_description)/urdf/materials.xacro" />
<xacro:include filename="$(find mr_robot_description)/urdf/mr_robot.trans" />
<xacro:include filename="$(find mr_robot_description)/urdf/mr_robot.gazebo" />
<link name="base_link">
  <inertial>
    <origin xyz="-0.013574303125599586 0.000311968832464644 0.02447814861373481" rpy="0 0 0"/>
    <mass value="12.51762642347825"/>
    <inertia ixx="0.228696" iyy="0.23871" izz="0.447823" ixy="-0.001289" iyz="3.7e-05" ixz="0.009889"/>
  </inertial>
  <visual>
    <origin xyz="0 0 0" rpy="0 0 0"/>
    <geometry>
      <mesh filename="package://mr_robot_description/meshes/base_link.stl" scale="0.001 0.001 0.001"/>
    </geometry>
    <material name="silver"/>
  </visual>
  <collision>
    <origin xyz="0 0 0" rpy="0 0 0"/>
    <geometry>
      <mesh filename="package://mr_robot_description/meshes/base_link.stl" scale="0.001 0.001 0.001"/>
    </geometry>
  </collision>
</link>

<link name="lidar_1">
  <inertial>
    <origin xyz="-0.08827260531446418 0.001000000201164283 0.07100205735814664" rpy="0 0 0"/>
    <mass value="1.1655252594710734"/>
    <inertia ixx="0.000543" iyy="0.000915" izz="0.001009" ixy="0.0" iyz="0.0" ixz="-0.000147"/>
  </inertial>
  <visual>
    <origin xyz="-0.1035 -0.0 -0.08" rpy="0 0 0"/>
    <geometry>
      <mesh filename="package://mr_robot_description/meshes/lidar_1.stl" scale="0.001 0.001 0.001"/>
    </geometry>
    <material name="blue"/>
  </visual>
  <collision>
    <origin xyz="-0.1035 -0.0 -0.08" rpy="0 0 0"/>
    <geometry>
      <mesh filename="package://mr_robot_description/meshes/lidar_1.stl" scale="0.001 0.001 0.001"/>
    </geometry>
  </collision>
</link>

<link name="motor_driver_1">
  <inertial>
    <origin xyz="0.0003955010685048353 0.00213711267527277 0.0064417706089128545" rpy="0 0 0"/>
    <mass value="0.05766626670761933"/>
    <inertia ixx="1.2e-05" iyy="9e-06" izz="1.5e-05" ixy="0.0" iyz="-2e-06" ixz="0.0"/>
  </inertial>
  <visual>
    <origin xyz="-0.0 -0.0 0.0" rpy="0 0 0"/>
    <geometry>
      <mesh filename="package://mr_robot_description/meshes/motor_driver_1.stl" scale="0.001 0.001 0.001"/>
    </geometry>
    <material name="dark_red"/>
  </visual>
  <collision>
    <origin xyz="-0.0 -0.0 0.0" rpy="0 0 0"/>
    <geometry>
      <mesh filename="package://mr_robot_description/meshes/motor_driver_1.stl" scale="0.001 0.001 0.001"/>
    </geometry>
  </collision>
</link>

<link name="PCB_1_1">
  <inertial>
    <origin xyz="-0.03640860143697952 0.05644244297723344 0.0007999999999997279" rpy="0 0 0"/>
    <mass value="0.09316520405438372"/>
    <inertia ixx="8.2e-05" iyy="4.1e-05" izz="0.000123" ixy="0.0" iyz="-0.0" ixz="0.0"/>
  </inertial>
  <visual>
    <origin xyz="-0.16625 0.15 0.0" rpy="0 0 0"/>
    <geometry>
      <mesh filename="package://mr_robot_description/meshes/PCB_1_1.stl" scale="0.001 0.001 0.001"/>
    </geometry>
    <material name="green"/>
  </visual>
  <collision>
    <origin xyz="-0.16625 0.15 0.0" rpy="0 0 0"/>
    <geometry>
      <mesh filename="package://mr_robot_description/meshes/PCB_1_1.stl" scale="0.001 0.001 0.001"/>
    </geometry>
  </collision>
</link>

<link name="PCB__1">
  <inertial>
    <origin xyz="-0.03643399332513472 -0.05640958374120579 0.0008000000000003021" rpy="0 0 0"/>
    <mass value="0.09316520405438372"/>
    <inertia ixx="8.2e-05" iyy="4.1e-05" izz="0.000123" ixy="0.0" iyz="-0.0" ixz="0.0"/>
  </inertial>
  <visual>
    <origin xyz="-0.16625 -0.15 -0.0" rpy="0 0 0"/>
    <geometry>
      <mesh filename="package://mr_robot_description/meshes/PCB__1.stl" scale="0.001 0.001 0.001"/>
    </geometry>
    <material name="green"/>
  </visual>
  <collision>
    <origin xyz="-0.16625 -0.15 -0.0" rpy="0 0 0"/>
    <geometry>
      <mesh filename="package://mr_robot_description/meshes/PCB__1.stl" scale="0.001 0.001 0.001"/>
    </geometry>
  </collision>
</link>

<link name="tyre_l_1">
  <inertial>
    <origin xyz="4.137530711784392e-07 -0.03712255732102415 -1.2111881497745003e-07" rpy="0 0 0"/>
    <mass value="1.983568904838765"/>
    <inertia ixx="0.002221" iyy="0.003828" izz="0.002221" ixy="-0.0" iyz="0.0" ixz="-0.0"/>
  </inertial>
  <visual>
    <origin xyz="-0.000791 -0.147386 -0.014723" rpy="0 0 0"/>
    <geometry>
      <mesh filename="package://mr_robot_description/meshes/tyre_l_1.stl" scale="0.001 0.001 0.001"/>
    </geometry>
    <material name="black"/>
  </visual>
  <collision>
    <origin xyz="-0.000791 -0.147386 -0.014723" rpy="0 0 0"/>
    <geometry>
      <mesh filename="package://mr_robot_description/meshes/tyre_l_1.stl" scale="0.001 0.001 0.001"/>
    </geometry>
  </collision>
</link>

<link name="tyre_r_1">
  <inertial>
    <origin xyz="-4.1375306849186755e-07 0.03716672560547965 -1.211188152480669e-07" rpy="0 0 0"/>
    <mass value="1.9850106278661588"/>
    <inertia ixx="0.002226" iyy="0.003828" izz="0.002226" ixy="0.0" iyz="-0.0" ixz="0.0"/>
  </inertial>
  <visual>
    <origin xyz="-0.000109 0.147386 -0.014723" rpy="0 0 0"/>
    <geometry>
      <mesh filename="package://mr_robot_description/meshes/tyre_r_1.stl" scale="0.001 0.001 0.001"/>
    </geometry>
    <material name="black"/>
  </visual>
  <collision>
    <origin xyz="-0.000109 0.147386 -0.014723" rpy="0 0 0"/>
    <geometry>
      <mesh filename="package://mr_robot_description/meshes/tyre_r_1.stl" scale="0.001 0.001 0.001"/>
    </geometry>
  </collision>
</link>

<link name="LiPo_3S_v2_1">
  <inertial>
    <origin xyz="0.03620000000000145 -0.03991462047942949 0.022424999999999796" rpy="0 0 0"/>
    <mass value="1.1316523601774637"/>
    <inertia ixx="0.004185" iyy="0.000601" izz="0.004409" ixy="-0.0" iyz="-0.0" ixz="0.0"/>
  </inertial>
  <visual>
    <origin xyz="0.173 0.0 0.0" rpy="0 0 0"/>
    <geometry>
      <mesh filename="package://mr_robot_description/meshes/LiPo_3S_v2_1.stl" scale="0.001 0.001 0.001"/>
    </geometry>
    <material name="orange"/>
  </visual>
  <collision>
    <origin xyz="0.173 0.0 0.0" rpy="0 0 0"/>
    <geometry>
      <mesh filename="package://mr_robot_description/meshes/LiPo_3S_v2_1.stl" scale="0.001 0.001 0.001"/>
    </geometry>
  </collision>
</link>

<link name="red_wire_1">
  <inertial>
    <origin xyz="-0.05960107486890705 0.0026232397316060113 0.012078506761870507" rpy="0 0 0"/>
    <mass value="0.016199442069398183"/>
    <inertia ixx="1e-06" iyy="1e-06" izz="1e-06" ixy="0.0" iyz="0.0" ixz="0.0"/>
  </inertial>
  <visual>
    <origin xyz="0.064 -0.073886 -0.0" rpy="0 0 0"/>
    <geometry>
      <mesh filename="package://mr_robot_description/meshes/red_wire_1.stl" scale="0.001 0.001 0.001"/>
    </geometry>
    <material name="red"/>
  </visual>
  <collision>
    <origin xyz="0.064 -0.073886 -0.0" rpy="0 0 0"/>
    <geometry>
      <mesh filename="package://mr_robot_description/meshes/red_wire_1.stl" scale="0.001 0.001 0.001"/>
    </geometry>
  </collision>
</link>

<link name="black_wire_1">
  <inertial>
    <origin xyz="-0.07060107486890682 0.002623239731605942 0.012078506761870535" rpy="0 0 0"/>
    <mass value="0.016199442069398183"/>
    <inertia ixx="1e-06" iyy="1e-06" izz="1e-06" ixy="0.0" iyz="0.0" ixz="0.0"/>
  </inertial>
  <visual>
    <origin xyz="0.064 -0.073886 -0.0" rpy="0 0 0"/>
    <geometry>
      <mesh filename="package://mr_robot_description/meshes/black_wire_1.stl" scale="0.001 0.001 0.001"/>
    </geometry>
    <material name="black"/>
  </visual>
  <collision>
    <origin xyz="0.064 -0.073886 -0.0" rpy="0 0 0"/>
    <geometry>
      <mesh filename="package://mr_robot_description/meshes/black_wire_1.stl" scale="0.001 0.001 0.001"/>
    </geometry>
  </collision>
</link>

<link name="upper_panel_1">
  <inertial>
    <origin xyz="-0.16981107647233692 -0.1874964863522696 0.01845928079506233" rpy="0 0 0"/>
    <mass value="7.649753398983414"/>
    <inertia ixx="0.111429" iyy="0.097265" izz="0.205922" ixy="1.5e-05" iyz="-5e-06" ixz="0.001292"/>
  </inertial>
  <visual>
    <origin xyz="-0.187506 -0.187494 -0.07" rpy="0 0 0"/>
    <geometry>
      <mesh filename="package://mr_robot_description/meshes/upper_panel_1.stl" scale="0.001 0.001 0.001"/>
    </geometry>
    <material name="translucent"/>
  </visual>
  <collision>
    <origin xyz="-0.187506 -0.187494 -0.07" rpy="0 0 0"/>
    <geometry>
      <mesh filename="package://mr_robot_description/meshes/upper_panel_1.stl" scale="0.001 0.001 0.001"/>
    </geometry>
  </collision>
</link>

<link name="RPi4ModelB_1">
  <inertial>
    <origin xyz="-0.037026936530551585 -0.000544166088421207 0.08100406173018841" rpy="0 0 0"/>
    <mass value="0.04363865099595201"/>
    <inertia ixx="1.3e-05" iyy="3e-05" izz="4e-05" ixy="0.0" iyz="-0.0" ixz="3e-06"/>
  </inertial>
  <visual>
    <origin xyz="-0.0 -0.0 -0.0" rpy="0 0 0"/>
    <geometry>
      <mesh filename="package://mr_robot_description/meshes/RPi4ModelB_1.stl" scale="0.001 0.001 0.001"/>
    </geometry>
    <material name="green"/>
  </visual>
  <collision>
    <origin xyz="-0.0 -0.0 -0.0" rpy="0 0 0"/>
    <geometry>
      <mesh filename="package://mr_robot_description/meshes/RPi4ModelB_1.stl" scale="0.001 0.001 0.001"/>
    </geometry>
  </collision>
</link>

<link name="V_Slot_1">
  <inertial>
    <origin xyz="4.426146948954823e-15 -0.16213021189797977 0.11568032411813599" rpy="0 0 0"/>
    <mass value="0.9613817576893465"/>
    <inertia ixx="0.004833" iyy="0.010478" izz="0.015232" ixy="0.0" iyz="-0.0" ixz="0.0"/>
  </inertial>
  <visual>
    <origin xyz="-0.001 -0.071886 -0.1143" rpy="0 0 0"/>
    <geometry>
      <mesh filename="package://mr_robot_description/meshes/V_Slot_1.stl" scale="0.001 0.001 0.001"/>
    </geometry>
    <material name="silver"/>
  </visual>
  <collision>
    <origin xyz="-0.001 -0.071886 -0.1143" rpy="0 0 0"/>
    <geometry>
      <mesh filename="package://mr_robot_description/meshes/V_Slot_1.stl" scale="0.001 0.001 0.001"/>
    </geometry>
  </collision>
</link>

<joint name="Rigid 26" type="fixed">
  <origin xyz="0.1035 0.0 0.08" rpy="0 0 3.14"/>
  <parent link="base_link"/>
  <child link="lidar_1"/>
</joint>

<joint name="Rigid 41" type="fixed">
  <origin xyz="0.0 0.0 0.0" rpy="0 0 0"/>
  <parent link="base_link"/>
  <child link="motor_driver_1"/>
</joint>

<joint name="Rigid 42" type="fixed">
  <origin xyz="0.16625 -0.15 0.0" rpy="0 0 0"/>
  <parent link="base_link"/>
  <child link="PCB_1_1"/>
</joint>

<joint name="Rigid 43" type="fixed">
  <origin xyz="0.16625 0.15 0.0" rpy="0 0 0"/>
  <parent link="base_link"/>
  <child link="PCB__1"/>
</joint>

<joint name="Revolute 10" type="continuous">
  <origin xyz="0.000791 0.147386 0.014723" rpy="0 0 0"/>
  <parent link="base_link"/>
  <child link="tyre_l_1"/>
  <axis xyz="-0.0 1.0 -0.0"/>
</joint>

<joint name="Revolute 9" type="continuous">
  <origin xyz="0.000109 -0.147386 0.014723" rpy="0 0 0"/>
  <parent link="base_link"/>
  <child link="tyre_r_1"/>
  <axis xyz="0.0 1.0 -0.0"/>
</joint>

<joint name="Rigid 53" type="fixed">
  <origin xyz="-0.173 0.0 0.0" rpy="0 0 0"/>
  <parent link="base_link"/>
  <child link="LiPo_3S_v2_1"/>
</joint>

<joint name="Rigid 60" type="fixed">
  <origin xyz="-0.064 0.073886 0.0" rpy="0 0 0"/>
  <parent link="base_link"/>
  <child link="red_wire_1"/>
</joint>

<joint name="Rigid 61" type="fixed">
  <origin xyz="-0.064 0.073886 0.0" rpy="0 0 0"/>
  <parent link="base_link"/>
  <child link="black_wire_1"/>
</joint>

<joint name="Rigid 62" type="fixed">
  <origin xyz="0.187506 0.187494 0.07" rpy="0 0 0"/>
  <parent link="base_link"/>
  <child link="upper_panel_1"/>
</joint>

<joint name="Rigid 63" type="fixed">
  <origin xyz="0.0 0.0 0.0" rpy="0 0 0"/>
  <parent link="base_link"/>
  <child link="RPi4ModelB_1"/>
</joint>

<joint name="Rigid 64" type="fixed">
  <origin xyz="0.001 0.062886 0.1143" rpy="0 0 0"/>
  <parent link="base_link"/>
  <child link="V_Slot_1"/>
</joint>

</robot>
